<sdf version='1.11'>
  <model name='human'>
    <link name='chest'>
      <inertial>
        <pose>-0.00019902280337225921 -0.00203130302736155 -0.037819464503959899 0 0 0</pose>
        <mass>1.01725518354323</mass>
        <inertia>
          <ixx>0.0031801711506863851</ixx>
          <ixy>2.3215723779200341e-07</ixy>
          <ixz>3.1962318710858549e-06</ixz>
          <iyy>0.003314632515231372</iyy>
          <iyz>-0.00032228233031600731</iyz>
          <izz>0.00064202333554569304</izz>
        </inertia>
      </inertial>
      <collision name='chest_box_collision'>
        <pose>0 0.0050000000000000001 -0.050000000000000003 0 0 0</pose>
        <geometry>
          <box>
            <size>0.1125 0.097500000000000003 0.14000000000000001</size>
          </box>
        </geometry>
      </collision>
      <collision name='chest_cylinder_collision_1'>
        <pose>0 -0.075699000000000002 0.037999999999999999 0 1.5707963267948966 0</pose>
        <geometry>
          <cylinder>
            <length>0.11459999999999999</length>
            <radius>0.0080000000000000002</radius>
          </cylinder>
        </geometry>
      </collision>
      <collision name='chest_fixed_joint_lump__neck_collision1_collision_2'>
        <pose>0 0.0134 0.051150000000000043 0 0 0</pose>
        <geometry>
          <box>
            <size>0.030200000000000001 0.0356 0.039600000000000003</size>
          </box>
        </geometry>
      </collision>
      <collision name='chest_fixed_joint_lump__neck_collision2_collision_3'>
        <pose>0 0.013427 0.053940000000000043 0 0 0</pose>
        <geometry>
          <box>
            <size>0.035499999999999997 0.024386399999999999 0.045179499999999997</size>
          </box>
        </geometry>
      </collision>
      <collision name='chest_fixed_joint_lump__neck_collision3_collision_4'>
        <pose>0 0.0134 0.030250000000000051 0 0 0</pose>
        <geometry>
          <box>
            <size>0.034200000000000001 0.035499999999999997 0.014999999999999999</size>
          </box>
        </geometry>
      </collision>
      <collision name='chest_fixed_joint_lump__head_collision1_collision_5'>
        <pose>-0.0002499984691190886 0.015306468801537991 0.1235513065115186 1.5707959999999983 -1.4912129999999999 -1.5707959999999981</pose>
        <geometry>
          <sphere>
            <radius>0.030539699999999999</radius>
          </sphere>
        </geometry>
      </collision>
      <collision name='chest_fixed_joint_lump__head_collision2_collision_6'>
        <pose>-0.00024999864647085382 0.016264169320519401 0.11676295739586889 1.5707959999999983 -1.4912129999999999 -1.5707959999999981</pose>
        <geometry>
          <sphere>
            <radius>0.028408599999999999</radius>
          </sphere>
        </geometry>
      </collision>
      <collision name='chest_fixed_joint_lump__head_collision3_collision_7'>
        <pose>-0.0002499985442047277 0.0049332325522251138 0.1202481863629407 1.5707959999999983 -1.4912129999999999 -1.5707959999999981</pose>
        <geometry>
          <sphere>
            <radius>0.0349883</radius>
          </sphere>
        </geometry>
      </collision>
      <visual name='chest_visual_visual'>
        <pose>0 0 0 -1.5707963270000003 0 0</pose>
        <geometry>
          <mesh>
            <scale>1 1 1</scale>
            <uri>meshes/chest.STL</uri>
          </mesh>
        </geometry>
      </visual>
      <visual name='chest_fixed_joint_lump__neck_visual_visual_1'>
        <pose>0 0.0134 0.02075000000000005 -1.5707963270000003 0 0</pose>
        <geometry>
          <mesh>
            <scale>1 1 1</scale>
            <uri>meshes/neck.STL</uri>
          </mesh>
        </geometry>
        <material>
          <diffuse>0 0 0 1</diffuse>
          <ambient>0 0 0 1</ambient>
        </material>
      </visual>
      <visual name='chest_fixed_joint_lump__head_visual_visual_2'>
        <pose>-0.018749999999999999 0.0134 0.064550000000000052 -3.270000019771135e-07 -1.4912130000000026 -1.5707959999999985</pose>
        <geometry>
          <mesh>
            <scale>1 1 1</scale>
            <uri>meshes/head.STL</uri>
          </mesh>
        </geometry>
        <material>
          <diffuse>0 0 0 1</diffuse>
          <ambient>0 0 0 1</ambient>
        </material>
      </visual>
    </link>
    <joint name='left_arm_upper' type='revolute'>
      <pose relative_to='chest'>-0.074700000000000003 0.0134 0 -3.1415923071795868 1.5707960010076636 8.1079225973594387e-17</pose>
      <parent>chest</parent>
      <child>left_arm</child>
      <axis>
        <xyz>0 0 -1</xyz>
        <limit>
          <lower>-3.1415926540000001</lower>
          <upper>3.1415926540000001</upper>
          <effort>7</effort>
          <velocity>20</velocity>
        </limit>
        <dynamics>
          <damping>0.036200000000000003</damping>
          <friction>0.0077999999999999996</friction>
          <spring_reference>0</spring_reference>
          <spring_stiffness>0</spring_stiffness>
        </dynamics>
      </axis>
    </joint>
    <link name='left_arm'>
      <pose relative_to='left_arm_upper'>0 0 0 0 0 0</pose>
      <inertial>
        <pose>0.080763000000000001 0.0018860000000000001 0.029108999999999999 0 0 0</pose>
        <mass>0.140880482426088</mass>
        <inertia>
          <ixx>2.0746461598375701e-05</ixx>
          <ixy>-2.8659021101734599e-11</ixy>
          <ixz>-6.7417528894394298e-06</ixz>
          <iyy>0.00012310039515784201</iyy>
          <iyz>-1.5929639449771301e-07</iyz>
          <izz>0.00011999284945507099</izz>
        </inertia>
      </inertial>
      <collision name='left_arm_collision_collision'>
        <pose>0.080500000000000002 0 0.029000000000000001 0 0 0</pose>
        <geometry>
          <box>
            <size>0.12709999999999999 0.048000000000000001 0.028000000000000001</size>
          </box>
        </geometry>
      </collision>
      <visual name='left_arm_visual_visual'>
        <pose>0 0 0 -1.5707963270000003 0 0</pose>
        <geometry>
          <mesh>
            <scale>1 1 1</scale>
            <uri>meshes/left_arm.STL</uri>
          </mesh>
        </geometry>
        <material>
          <diffuse>0 0 0 1</diffuse>
          <ambient>0 0 0 1</ambient>
        </material>
      </visual>
    </link>
    <joint name='left_arm_lower' type='revolute'>
      <pose relative_to='left_arm'>0.13600000000000001 0 0.049549999999999997 0 0 0</pose>
      <parent>left_arm</parent>
      <child>left_hand</child>
      <axis>
        <xyz>0 0 -1</xyz>
        <limit>
          <lower>-3.1415926540000001</lower>
          <upper>3.1415926540000001</upper>
          <effort>3</effort>
          <velocity>20</velocity>
        </limit>
        <dynamics>
          <damping>0.036200000000000003</damping>
          <friction>0.0077999999999999996</friction>
          <spring_reference>0</spring_reference>
          <spring_stiffness>0</spring_stiffness>
        </dynamics>
      </axis>
    </joint>
    <link name='left_hand'>
      <pose relative_to='left_arm_lower'>0 0 0 0 0 0</pose>
      <inertial>
        <pose>0.063648999999999997 0 0.0013190000000000001 0 0 0</pose>
        <mass>0.024044269196268502</mass>
        <inertia>
          <ixx>1.94691318232501e-06</ixx>
          <ixy>1.9798400242031498e-12</ixy>
          <ixz>1.70538796340321e-12</ixz>
          <iyy>4.9981652993954002e-05</iyy>
          <iyz>7.0639482370012499e-13</iyz>
          <izz>5.1889171468805399e-05</izz>
        </inertia>
      </inertial>
      <collision name='left_hand_end_collision_collision'>
        <pose>0.13500000000000001 0 0.0015 0 0 0</pose>
        <geometry>
          <cylinder>
            <length>0.0030000000000000001</length>
            <radius>0.02</radius>
          </cylinder>
        </geometry>
      </collision>
      <collision name='left_hand_base_collision_collision_1'>
        <pose>0 0 0.00050000000000000001 0 0 0</pose>
        <geometry>
          <cylinder>
            <length>0.0050000000000000001</length>
            <radius>0.0146</radius>
          </cylinder>
        </geometry>
      </collision>
      <collision name='left_hand_connection_collision_collision_2'>
        <pose>0.060122000000000002 0 0.0015 0 0 0</pose>
        <geometry>
          <box>
            <size>0.120244 0.027 0.0030000000000000001</size>
          </box>
        </geometry>
      </collision>
      <visual name='left_hand_visual_visual'>
        <pose>0 0 0 -1.5707963270000003 0 0</pose>
        <geometry>
          <mesh>
            <scale>1 1 1</scale>
            <uri>meshes/left_hand.STL</uri>
          </mesh>
        </geometry>
        <material>
          <diffuse>0 0 0 1</diffuse>
          <ambient>0 0 0 1</ambient>
        </material>
      </visual>
    </link>
    <joint name='left_hip_yaw' type='revolute'>
      <pose relative_to='chest'>-0.044999999999999998 0.0133599999999985 -0.16994999999999999 0 0 0</pose>
      <parent>chest</parent>
      <child>left_leg_yaw</child>
      <axis>
        <xyz>0 0 -1</xyz>
        <limit>
          <lower>-3.1415926540000001</lower>
          <upper>3.1415926540000001</upper>
          <effort>7</effort>
          <velocity>20</velocity>
        </limit>
        <dynamics>
          <damping>0.036200000000000003</damping>
          <friction>0.0077999999999999996</friction>
          <spring_reference>0</spring_reference>
          <spring_stiffness>0</spring_stiffness>
        </dynamics>
      </axis>
    </joint>
    <link name='left_leg_yaw'>
      <pose relative_to='left_hip_yaw'>0 0 0 0 0 0</pose>
      <inertial>
        <pose>0 0.0032850000000000002 -0.029821 0 0 0</pose>
        <mass>0.058662024462932297</mass>
        <inertia>
          <ixx>3.0496686582707501e-05</ixx>
          <ixy>-8.4677743033588304e-14</ixy>
          <ixz>8.5574380306308406e-14</ixz>
          <iyy>1.16928645977672e-05</iyy>
          <iyz>-9.4199503165967801e-08</iyz>
          <izz>3.04113434807083e-05</izz>
        </inertia>
      </inertial>
      <collision name='left_leg_yaw_collision_collision'>
        <pose>0 0.0051500000000000001 -0.022499999999999999 0 0 0</pose>
        <geometry>
          <box>
            <size>0.041000000000000002 0.063700000000000007 0.0030000000000000001</size>
          </box>
        </geometry>
      </collision>
      <visual name='left_leg_yaw_visual_visual'>
        <pose>0 0 0 -1.5707963270000003 0 0</pose>
        <geometry>
          <mesh>
            <scale>1 1 1</scale>
            <uri>meshes/left_leg_yaw.STL</uri>
          </mesh>
        </geometry>
        <material>
          <diffuse>0 0 0 1</diffuse>
          <ambient>0 0 0 1</ambient>
        </material>
      </visual>
    </link>
    <joint name='left_hip_roll' type='revolute'>
      <pose relative_to='left_leg_yaw'>0 -0.0292 -0.055 0 0 0</pose>
      <parent>left_leg_yaw</parent>
      <child>left_leg_roll</child>
      <axis>
        <xyz>0 1 0</xyz>
        <limit>
          <lower>-3.1415926540000001</lower>
          <upper>3.1415926540000001</upper>
          <effort>7</effort>
          <velocity>20</velocity>
        </limit>
        <dynamics>
          <damping>0.036200000000000003</damping>
          <friction>0.0077999999999999996</friction>
          <spring_reference>0</spring_reference>
          <spring_stiffness>0</spring_stiffness>
        </dynamics>
      </axis>
    </joint>
    <link name='left_leg_roll'>
      <pose relative_to='left_hip_roll'>0 0 0 0 0 0</pose>
      <inertial>
        <pose>2.5000000000000001e-05 0.010978 -0.014083999999999999 0 0 0</pose>
        <mass>0.17675216665704899</mass>
        <inertia>
          <ixx>6.1790335519862398e-05</ixx>
          <ixy>-9.41308133856575e-10</ixy>
          <ixz>-2.1169089800936899e-07</ixz>
          <iyy>6.5889939337192494e-05</iyy>
          <iyz>-2.14817110544029e-07</iyz>
          <izz>3.9028076120466002e-05</izz>
        </inertia>
      </inertial>
      <collision name='left_leg_roll_upper_collision_collision'>
        <pose>0 0.03065 -0.018117000000000001 0 0 0</pose>
        <geometry>
          <box>
            <size>0.050200000000000002 0.064299999999999996 0.065255199999999999</size>
          </box>
        </geometry>
      </collision>
      <collision name='left_leg_roll_lower_collision_collision_1'>
        <pose>0 -0.039750000000000001 -0.014838 0 0 0</pose>
        <geometry>
          <box>
            <size>0.028996999999999998 0.0035000000000000001 0.055392799999999999</size>
          </box>
        </geometry>
      </collision>
      <collision name='left_leg_roll_down_collision_collision_2'>
        <pose>1.4e-05 -0.019 -0.01755 0 0 0</pose>
        <geometry>
          <box>
            <size>0.040388399999999998 0.037999999999999999 0.061100599999999998</size>
          </box>
        </geometry>
      </collision>
      <visual name='left_leg_roll_visual_visual'>
        <pose>0 0 0 -1.5707963270000003 0 0</pose>
        <geometry>
          <mesh>
            <scale>1 1 1</scale>
            <uri>meshes/left_leg_roll.STL</uri>
          </mesh>
        </geometry>
        <material>
          <diffuse>0 0 0 1</diffuse>
          <ambient>0 0 0 1</ambient>
        </material>
      </visual>
    </link>
    <joint name='left_hip_pitch' type='revolute'>
      <pose relative_to='left_leg_roll'>-0.028999694999999999 0.0292 0.000132953 -0.34059799999999818 1.5659320000000612 2.8009909999999976</pose>
      <parent>left_leg_roll</parent>
      <child>left_leg_pitch</child>
      <axis>
        <xyz>0 0 -1</xyz>
        <limit>
          <lower>-3.1415926540000001</lower>
          <upper>3.1415926540000001</upper>
          <effort>10</effort>
          <velocity>20</velocity>
        </limit>
        <dynamics>
          <damping>0.041399999999999999</damping>
          <friction>0.1179</friction>
          <spring_reference>0</spring_reference>
          <spring_stiffness>0</spring_stiffness>
        </dynamics>
      </axis>
    </joint>
    <link name='left_leg_pitch'>
      <pose relative_to='left_hip_pitch'>0 0 0 0 0 0</pose>
      <inertial>
        <pose>0.037596999999999998 0 -0.027982 0 0 0</pose>
        <mass>0.027887725075667901</mass>
        <inertia>
          <ixx>2.41537468742227e-06</ixx>
          <ixy>3.2274965794789498e-14</ixy>
          <ixz>4.7964487075471796e-12</ixz>
          <iyy>1.14633756275734e-05</iyy>
          <iyz>7.7934947477887403e-15</iyz>
          <izz>1.3716039319153201e-05</izz>
        </inertia>
      </inertial>
      <collision name='left_leg_pitch_big_collision_collision'>
        <pose>0.11475 0 -0.028992 0 0 0</pose>
        <geometry>
          <box>
            <size>0.059499999999999997 0.029000000000000001 0.045984799999999999</size>
          </box>
        </geometry>
      </collision>
      <collision name='left_leg_pitch_p_one0_collision_collision_1'>
        <pose>0.11194999999999999 0 -0.012749999999999999 0 0 0</pose>
        <geometry>
          <box>
            <size>0.065100000000000005 0.029000000000000001 0.0015</size>
          </box>
        </geometry>
      </collision>
      <collision name='left_leg_pitch_p_one1_collision_collision_2'>
        <pose>0.11194999999999999 0 -0.012749999999999999 0 0 0</pose>
        <geometry>
          <box>
            <size>0.053900000000000003 0.0402 0.0015</size>
          </box>
        </geometry>
      </collision>
      <collision name='left_leg_pitch_p_two0_collision_collision_3'>
        <pose>0.11194999999999999 0 -0.045249999999999999 0 0 0</pose>
        <geometry>
          <box>
            <size>0.065100000000000005 0.029000000000000001 0.0015</size>
          </box>
        </geometry>
      </collision>
      <collision name='left_leg_pitch_p_two1_collision_collision_4'>
        <pose>0.11194999999999999 0 -0.045249999999999999 0 0 0</pose>
        <geometry>
          <box>
            <size>0.053900000000000003 0.0402 0.0015</size>
          </box>
        </geometry>
      </collision>
      <visual name='left_leg_pitch_visual_visual'>
        <pose>0 0 0 -1.5707963270000003 0 0</pose>
        <geometry>
          <mesh>
            <scale>1 1 1</scale>
            <uri>meshes/left_leg_pitch.STL</uri>
          </mesh>
        </geometry>
        <material>
          <diffuse>0 0 0 1</diffuse>
          <ambient>0 0 0 1</ambient>
        </material>
      </visual>
    </link>
    <joint name='left_knee' type='revolute'>
      <pose relative_to='left_leg_pitch'>0.13002367748412599 -0.000211229839968 -0.0049039448874059997 0 0 0</pose>
      <parent>left_leg_pitch</parent>
      <child>left_leg_knee</child>
      <axis>
        <xyz>0 0 1</xyz>
        <limit>
          <lower>-3.1415926540000001</lower>
          <upper>3.1415926540000001</upper>
          <effort>10</effort>
          <velocity>20</velocity>
        </limit>
        <dynamics>
          <damping>0.034700000000000002</damping>
          <friction>0.0843</friction>
          <spring_reference>0</spring_reference>
          <spring_stiffness>0</spring_stiffness>
        </dynamics>
      </axis>
    </joint>
    <link name='left_leg_knee'>
      <pose relative_to='left_knee'>0 0 0 0 0 0</pose>
      <inertial>
        <pose>0.084360000000000004 0 -0.024128 0 0 0</pose>
        <mass>0.0328192125267944</mass>
        <inertia>
          <ixx>1.9489049933254499e-06</ixx>
          <ixy>2.35500388345378e-20</ixy>
          <ixz>-4.79645500496334e-12</ixz>
          <iyy>4.3073341622455502e-05</iyy>
          <iyz>9.3300803217153103e-22</iyz>
          <izz>4.4968042537653101e-05</izz>
        </inertia>
      </inertial>
      <collision name='left_leg_knee_collision0_collision'>
        <pose>0 0 -0.049750000000000003 0 0 0</pose>
        <geometry>
          <cylinder>
            <length>0.0054999999999999997</length>
            <radius>0.014</radius>
          </cylinder>
        </geometry>
      </collision>
      <collision name='left_leg_knee_collision1_collision_1'>
        <pose>0 0 0.0030000000000000001 0 0 0</pose>
        <geometry>
          <cylinder>
            <length>0.0054999999999999997</length>
            <radius>0.014</radius>
          </cylinder>
        </geometry>
      </collision>
      <collision name='left_leg_knee_collision2_collision_2'>
        <pose>0.13036 0 -0.049750000000000003 0 0 0</pose>
        <geometry>
          <cylinder>
            <length>0.0054999999999999997</length>
            <radius>0.014</radius>
          </cylinder>
        </geometry>
      </collision>
      <collision name='left_leg_knee_collision3_collision_3'>
        <pose>0.13036 0 0.0030000000000000001 0 0 0</pose>
        <geometry>
          <cylinder>
            <length>0.0054999999999999997</length>
            <radius>0.014</radius>
          </cylinder>
        </geometry>
      </collision>
      <visual name='left_leg_knee_visual_visual'>
        <pose>0 0 0 -1.5707963270000003 0 0</pose>
        <geometry>
          <mesh>
            <scale>1 1 1</scale>
            <uri>meshes/left_leg_knee.STL</uri>
          </mesh>
        </geometry>
        <material>
          <diffuse>0 0 0 1</diffuse>
          <ambient>0 0 0 1</ambient>
        </material>
      </visual>
    </link>
    <joint name='left_ankle_pitch' type='revolute'>
      <pose relative_to='left_leg_knee'>0.12999846217997499 -0.000211229839968 0.00059599731123800002 -0.17622265358979133 1.5614826535898316 2.9669936535897934</pose>
      <parent>left_leg_knee</parent>
      <child>left_leg_ankle</child>
      <axis>
        <xyz>1 0 0</xyz>
        <limit>
          <lower>-3.1415926540000001</lower>
          <upper>3.1415926540000001</upper>
          <effort>10</effort>
          <velocity>20</velocity>
        </limit>
        <dynamics>
          <damping>0.036200000000000003</damping>
          <friction>0.0077999999999999996</friction>
          <spring_reference>0</spring_reference>
          <spring_stiffness>0</spring_stiffness>
        </dynamics>
      </axis>
    </joint>
    <link name='left_leg_ankle'>
      <pose relative_to='left_ankle_pitch'>0 0 0 0 0 0</pose>
      <inertial>
        <pose>0.023591000000000001 -0.016018000000000001 0.014279999999999999 0 0 0</pose>
        <mass>0.173948205448793</mass>
        <inertia>
          <ixx>6.1525563546113303e-05</ixx>
          <ixy>-4.3529887410332497e-11</ixy>
          <ixz>1.07316479776985e-07</ixz>
          <iyy>6.5767469559665899e-05</iyy>
          <iyz>-1.9005632960375801e-07</iyz>
          <izz>3.8828440030109099e-05</izz>
        </inertia>
      </inertial>
      <collision name='left_leg_ankle_small_collision_collision'>
        <pose>0.023508000000000001 -0.043499999999999997 0.014751999999999999 0 0 0</pose>
        <geometry>
          <box>
            <size>0.028984800000000002 0.041000000000000002 0.055496200000000002</size>
          </box>
        </geometry>
      </collision>
      <collision name='left_leg_ankle_small11_collision_collision_1'>
        <pose>0.0235 -0.058250000000000003 0.01755 0 0 0</pose>
        <geometry>
          <box>
            <size>0.029000000000000001 0.0044999999999999997 0.061100000000000002</size>
          </box>
        </geometry>
      </collision>
      <collision name='left_leg_ankle_small12_collision_collision_2'>
        <pose>0.0235 -0.058250000000000003 0.01755 0 0 0</pose>
        <geometry>
          <box>
            <size>0.0402 0.0044999999999999997 0.0499</size>
          </box>
        </geometry>
      </collision>
      <collision name='left_leg_ankle_small21_collision_collision_3'>
        <pose>0.0235 -0.028739000000000001 0.01755 0 0 0</pose>
        <geometry>
          <box>
            <size>0.029000000000000001 0.0044999999999999997 0.061100000000000002</size>
          </box>
        </geometry>
      </collision>
      <collision name='left_leg_ankle_small22_collision_collision_4'>
        <pose>0.0235 -0.028739000000000001 0.01755 0 0 0</pose>
        <geometry>
          <box>
            <size>0.0402 0.0044999999999999997 0.0499</size>
          </box>
        </geometry>
      </collision>
      <collision name='left_leg_ankle_big_collision_collision_5'>
        <pose>0.0235 0 0.01525 0 0 0</pose>
        <geometry>
          <box>
            <size>0.045999999999999999 0.029000000000000001 0.059499999999999997</size>
          </box>
        </geometry>
      </collision>
      <collision name='left_leg_ankle_big11_collision_collision_6'>
        <pose>0.03875 0 0.01805 0 0 0</pose>
        <geometry>
          <box>
            <size>0.0035000000000000001 0.029000000000000001 0.065100000000000005</size>
          </box>
        </geometry>
      </collision>
      <collision name='left_leg_ankle_big12_collision_collision_7'>
        <pose>0.03875 0 0.01805 0 0 0</pose>
        <geometry>
          <box>
            <size>0.0035000000000000001 0.0402 0.053900000000000003</size>
          </box>
        </geometry>
      </collision>
      <collision name='left_leg_ankle_big21_collision_collision_8'>
        <pose>0.0080000000000000002 0 0.01805 0 0 0</pose>
        <geometry>
          <box>
            <size>0.0030000000000000001 0.029000000000000001 0.065100000000000005</size>
          </box>
        </geometry>
      </collision>
      <collision name='left_leg_ankle_big22_collision_collision_9'>
        <pose>0.0080000000000000002 0 0.01805 0 0 0</pose>
        <geometry>
          <box>
            <size>0.0035000000000000001 0.0402 0.053900000000000003</size>
          </box>
        </geometry>
      </collision>
      <collision name='left_leg_ankle_upper_collision_collision_10'>
        <pose>0.0235 0.02785 0.0070000000000000001 0 0 0</pose>
        <geometry>
          <box>
            <size>0.039 0.0027000000000000001 0.029999999999999999</size>
          </box>
        </geometry>
      </collision>
      <visual name='left_leg_ankle_visual_visual'>
        <pose>0 0 0 -1.5707963270000003 0 0</pose>
        <geometry>
          <mesh>
            <scale>1 1 1</scale>
            <uri>meshes/left_leg_ankle.STL</uri>
          </mesh>
        </geometry>
        <material>
          <diffuse>0 0 0 1</diffuse>
          <ambient>0 0 0 1</ambient>
        </material>
      </visual>
    </link>
    <joint name='left_ankle_roll' type='revolute'>
      <pose relative_to='left_leg_ankle'>0.023387000000000002 -0.069538000000000003 -0.000113445 0 0 0</pose>
      <parent>left_leg_ankle</parent>
      <child>left_foot</child>
      <axis>
        <xyz>0 -1 0</xyz>
        <limit>
          <lower>-3.1415926540000001</lower>
          <upper>3.1415926540000001</upper>
          <effort>7</effort>
          <velocity>20</velocity>
        </limit>
        <dynamics>
          <damping>0.036200000000000003</damping>
          <friction>0.0077999999999999996</friction>
          <spring_reference>0</spring_reference>
          <spring_stiffness>0</spring_stiffness>
        </dynamics>
      </axis>
    </joint>
    <link name='left_foot'>
      <pose relative_to='left_ankle_roll'>0 0 0 0 0 0</pose>
      <inertial>
        <pose>-0.012987 0.068288000000000001 -0.035867999999999997 0 0 0</pose>
        <mass>0.144176668751163</mass>
        <inertia>
          <ixx>0.00014149565462157499</ixx>
          <ixy>-1.52740202739877e-09</ixy>
          <ixz>1.9349728888557201e-07</ixz>
          <iyy>5.0645258641957197e-05</iyy>
          <iyz>-3.3396462913510601e-07</iyz>
          <izz>0.000183700741709755</izz>
        </inertia>
      </inertial>
      <collision name='left_foot_box1_collision_collision'>
        <pose>-0.016188000000000001 0.066000000000000003 -0.040925999999999997 0 0 0</pose>
        <geometry>
          <box>
            <size>0.089999999999999997 0.126 0.016</size>
          </box>
        </geometry>
      </collision>
      <collision name='left_foot_box2_collision_collision_1'>
        <pose>-0.016211 0.066022999999999998 -0.040925999999999997 0 0 0</pose>
        <geometry>
          <box>
            <size>0.065954399999999996 0.149954 0.012</size>
          </box>
        </geometry>
      </collision>
      <collision name='left_foot_box3_collision_collision_2'>
        <pose>-0.016188000000000001 0.066000000000000003 -0.040925999999999997 0 0 0</pose>
        <geometry>
          <box>
            <size>0.086999999999999994 0.14699999999999999 0.0060000000000000001</size>
          </box>
        </geometry>
      </collision>
      <collision name='left_foot_box4_collision_collision_3'>
        <pose>-0.016171999999999999 0.14108599999999999 -0.037588999999999997 0 0 0</pose>
        <geometry>
          <box>
            <size>0.089999999999999997 0.0058276400000000003 0.018674400000000001</size>
          </box>
        </geometry>
      </collision>
      <visual name='left_foot_visual_visual'>
        <pose>0 0 0 -1.5707963270000003 0 0</pose>
        <geometry>
          <mesh>
            <scale>1 1 1</scale>
            <uri>meshes/left_foot.STL</uri>
          </mesh>
        </geometry>
        <material>
          <diffuse>0 0 0 1</diffuse>
          <ambient>0 0 0 1</ambient>
        </material>
      </visual>
    </link>
    <joint name='right_arm_upper' type='revolute'>
      <pose relative_to='chest'>0.074700000000000003 0.0134 0 0 1.5707959999869179 0</pose>
      <parent>chest</parent>
      <child>right_arm</child>
      <axis>
        <xyz>0 0 1</xyz>
        <limit>
          <lower>-3.1415926540000001</lower>
          <upper>3.1415926540000001</upper>
          <effort>7</effort>
          <velocity>20</velocity>
        </limit>
        <dynamics>
          <damping>0.036200000000000003</damping>
          <friction>0.0077999999999999996</friction>
          <spring_reference>0</spring_reference>
          <spring_stiffness>0</spring_stiffness>
        </dynamics>
      </axis>
    </joint>
    <link name='right_arm'>
      <pose relative_to='right_arm_upper'>0 0 0 0 0 0</pose>
      <inertial>
        <pose>0.080811999999999995 -0.0018710000000000001 0.029107999999999998 0 0 0</pose>
        <mass>0.140880482426088</mass>
        <inertia>
          <ixx>2.0746461598375701e-05</ixx>
          <ixy>3.0340088781543498e-07</ixy>
          <ixz>-6.7417528894395102e-06</ixz>
          <iyy>0.00012310039515784201</iyy>
          <iyz>1.5929818113849301e-07</iyz>
          <izz>0.00011999284945507099</izz>
        </inertia>
      </inertial>
      <collision name='right_arm_collision_collision'>
        <pose>0.080500000000000002 0 0.029000000000000001 0 0 0</pose>
        <geometry>
          <box>
            <size>0.12709999999999999 0.048000000000000001 0.028000000000000001</size>
          </box>
        </geometry>
      </collision>
      <visual name='right_arm_visual_visual'>
        <pose>0 0 0 -1.5707963270000003 0 0</pose>
        <geometry>
          <mesh>
            <scale>1 1 1</scale>
            <uri>meshes/right_arm.STL</uri>
          </mesh>
        </geometry>
        <material>
          <diffuse>0 0 0 1</diffuse>
          <ambient>0 0 0 1</ambient>
        </material>
      </visual>
    </link>
    <joint name='right_arm_lower' type='revolute'>
      <pose relative_to='right_arm'>0.13600000000000001 0 0.052549999999999999 0 0 0</pose>
      <parent>right_arm</parent>
      <child>right_hand</child>
      <axis>
        <xyz>0 0 1</xyz>
        <limit>
          <lower>-3.1415926540000001</lower>
          <upper>3.1415926540000001</upper>
          <effort>3</effort>
          <velocity>20</velocity>
        </limit>
        <dynamics>
          <damping>0.036200000000000003</damping>
          <friction>0.0077999999999999996</friction>
          <spring_reference>0</spring_reference>
          <spring_stiffness>0</spring_stiffness>
        </dynamics>
      </axis>
    </joint>
    <link name='right_hand'>
      <pose relative_to='right_arm_lower'>0 0 0 0 0 0</pose>
      <inertial>
        <pose>0.063648999999999997 0 -0.001681 0 0 0</pose>
        <mass>0.024044269196268502</mass>
        <inertia>
          <ixx>1.94691318232501e-06</ixx>
          <ixy>-1.9798400205047599e-12</ixy>
          <ixz>1.70538796039851e-12</ixz>
          <iyy>4.9981652993954097e-05</iyy>
          <iyz>-7.0639482380154195e-13</iyz>
          <izz>5.1889171468805501e-05</izz>
        </inertia>
      </inertial>
      <collision name='right_hand_end_collision_collision'>
        <pose>0.13500000000000001 0 -0.0015 0 0 0</pose>
        <geometry>
          <cylinder>
            <length>0.0030000000000000001</length>
            <radius>0.02</radius>
          </cylinder>
        </geometry>
      </collision>
      <collision name='right_hand_base_collision_collision_1'>
        <pose>0 0 -0.0025000000000000001 0 0 0</pose>
        <geometry>
          <cylinder>
            <length>0.0050000000000000001</length>
            <radius>0.0146</radius>
          </cylinder>
        </geometry>
      </collision>
      <collision name='right_hand_connection_collision_collision_2'>
        <pose>0.060122000000000002 0 -0.0015 0 0 0</pose>
        <geometry>
          <box>
            <size>0.120244 0.027 0.0030000000000000001</size>
          </box>
        </geometry>
      </collision>
      <visual name='right_hand_visual_visual'>
        <pose>0 0 0 -1.5707963270000003 0 0</pose>
        <geometry>
          <mesh>
            <scale>1 1 1</scale>
            <uri>meshes/right_hand.STL</uri>
          </mesh>
        </geometry>
        <material>
          <diffuse>0 0 0 1</diffuse>
          <ambient>0 0 0 1</ambient>
        </material>
      </visual>
    </link>
    <joint name='right_hip_yaw' type='revolute'>
      <pose relative_to='chest'>0.044999999999999998 0.01336 -0.16994999999999999 0 0 0</pose>
      <parent>chest</parent>
      <child>right_leg_yaw</child>
      <axis>
        <xyz>0 0 -1</xyz>
        <limit>
          <lower>-3.1415926540000001</lower>
          <upper>3.1415926540000001</upper>
          <effort>7</effort>
          <velocity>20</velocity>
        </limit>
        <dynamics>
          <damping>0.036200000000000003</damping>
          <friction>0.0077999999999999996</friction>
          <spring_reference>0</spring_reference>
          <spring_stiffness>0</spring_stiffness>
        </dynamics>
      </axis>
    </joint>
    <link name='right_leg_yaw'>
      <pose relative_to='right_hip_yaw'>0 0 0 0 0 0</pose>
      <inertial>
        <pose>0 0.0032850000000000002 -0.029821 0 0 0</pose>
        <mass>0.0586620244629322</mass>
        <inertia>
          <ixx>3.0496686583123601e-05</ixx>
          <ixy>-3.16154434574983e-14</ixy>
          <ixz>-1.34169348176914e-13</ixz>
          <iyy>1.16928645977672e-05</iyy>
          <iyz>-9.4199503115753094e-08</iyz>
          <izz>3.0411343480292098e-05</izz>
        </inertia>
      </inertial>
      <collision name='right_leg_yaw_collision_collision'>
        <pose>0 0.0051500000000000001 -0.022499999999999999 0 0 0</pose>
        <geometry>
          <box>
            <size>0.041000000000000002 0.063700000000000007 0.0030000000000000001</size>
          </box>
        </geometry>
      </collision>
      <visual name='right_leg_yaw_visual_visual'>
        <pose>0 0 0 -1.5707963270000003 0 0</pose>
        <geometry>
          <mesh>
            <scale>1 1 1</scale>
            <uri>meshes/right_leg_yaw.STL</uri>
          </mesh>
        </geometry>
        <material>
          <diffuse>0 0 0 1</diffuse>
          <ambient>0 0 0 1</ambient>
        </material>
      </visual>
    </link>
    <joint name='right_hip_roll' type='revolute'>
      <pose relative_to='right_leg_yaw'>0 -0.0292 -0.055 0 -0.0064780000000000003 0</pose>
      <parent>right_leg_yaw</parent>
      <child>right_leg_roll</child>
      <axis>
        <xyz>0 -1 0</xyz>
        <limit>
          <lower>-3.1415926540000001</lower>
          <upper>3.1415926540000001</upper>
          <effort>7</effort>
          <velocity>20</velocity>
        </limit>
        <dynamics>
          <damping>0.036200000000000003</damping>
          <friction>0.0077999999999999996</friction>
          <spring_reference>0</spring_reference>
          <spring_stiffness>0</spring_stiffness>
        </dynamics>
      </axis>
    </joint>
    <link name='right_leg_roll'>
      <pose relative_to='right_hip_roll'>0 0 0 0 0 0</pose>
      <inertial>
        <pose>9.0000000000000006e-05 0.010978 -0.014083999999999999 0 0 0</pose>
        <mass>0.176752167034151</mass>
        <inertia>
          <ixx>6.1791798147460997e-05</ixx>
          <ixy>4.3532300340763102e-11</ixy>
          <ixz>-1.07327270209975e-07</ixz>
          <iyy>6.5889939430164294e-05</iyy>
          <iyz>-2.14819182994814e-07</iyz>
          <izz>3.9026613600567697e-05</izz>
        </inertia>
      </inertial>
      <collision name='right_leg_roll_upper_collision_collision'>
        <pose>0 0.03065 -0.018117000000000001 0 0 0</pose>
        <geometry>
          <box>
            <size>0.050200000000000002 0.064299999999999996 0.065255199999999999</size>
          </box>
        </geometry>
      </collision>
      <collision name='right_leg_roll_lower_collision_collision_1'>
        <pose>0 -0.039750000000000001 -0.014838 0 0 0</pose>
        <geometry>
          <box>
            <size>0.028996999999999998 0.0035000000000000001 0.055392799999999999</size>
          </box>
        </geometry>
      </collision>
      <collision name='right_leg_roll_down_collision_collision_2'>
        <pose>1.4e-05 -0.019 -0.01755 0 0 0</pose>
        <geometry>
          <box>
            <size>0.040388399999999998 0.037999999999999999 0.061100599999999998</size>
          </box>
        </geometry>
      </collision>
      <visual name='right_leg_roll_visual_visual'>
        <pose>0 0 0 -1.5707963270000003 0 0</pose>
        <geometry>
          <mesh>
            <scale>1 1 1</scale>
            <uri>meshes/right_leg_roll.STL</uri>
          </mesh>
        </geometry>
        <material>
          <diffuse>0 0 0 1</diffuse>
          <ambient>0 0 0 1</ambient>
        </material>
      </visual>
    </link>
    <joint name='right_hip_pitch' type='revolute'>
      <pose relative_to='right_leg_roll'>0.029000000000000001 0.0292 0 1.5707799999999754 1.5670300000001207 1.5707999999999536</pose>
      <parent>right_leg_roll</parent>
      <child>right_leg_pitch</child>
      <axis>
        <xyz>0 0 1</xyz>
        <limit>
          <lower>-3.1415926540000001</lower>
          <upper>3.1415926540000001</upper>
          <effort>10</effort>
          <velocity>20</velocity>
        </limit>
        <dynamics>
          <damping>0.041399999999999999</damping>
          <friction>0.1179</friction>
          <spring_reference>0</spring_reference>
          <spring_stiffness>0</spring_stiffness>
        </dynamics>
      </axis>
    </joint>
    <link name='right_leg_pitch'>
      <pose relative_to='right_hip_pitch'>0 0 0 0 0 0</pose>
      <inertial>
        <pose>0.037596999999999998 0 -0.030018 0 0 0</pose>
        <mass>0.027887725075667901</mass>
        <inertia>
          <ixx>2.4153746871926199e-06</ixx>
          <ixy>-7.4854894278663796e-14</ixy>
          <ixz>-4.7964209833556204e-12</ixz>
          <iyy>1.14633756278031e-05</iyy>
          <iyz>1.8075310725767399e-14</iyz>
          <izz>1.3716039319153301e-05</izz>
        </inertia>
      </inertial>
      <collision name='right_leg_pitch_big_collision_collision'>
        <pose>0.11475 0 -0.028992 0 0 0</pose>
        <geometry>
          <box>
            <size>0.059499999999999997 0.029000000000000001 0.045984799999999999</size>
          </box>
        </geometry>
      </collision>
      <collision name='right_leg_pitch_p_one0_collision_collision_1'>
        <pose>0.11194999999999999 0 -0.012749999999999999 0 0 0</pose>
        <geometry>
          <box>
            <size>0.065100000000000005 0.029000000000000001 0.0015</size>
          </box>
        </geometry>
      </collision>
      <collision name='right_leg_pitch_p_one1_collision_collision_2'>
        <pose>0.11194999999999999 0 -0.012749999999999999 0 0 0</pose>
        <geometry>
          <box>
            <size>0.053900000000000003 0.0402 0.0015</size>
          </box>
        </geometry>
      </collision>
      <collision name='right_leg_pitch_p_two0_collision_collision_3'>
        <pose>0.11194999999999999 0 -0.045249999999999999 0 0 0</pose>
        <geometry>
          <box>
            <size>0.065100000000000005 0.029000000000000001 0.0015</size>
          </box>
        </geometry>
      </collision>
      <collision name='right_leg_pitch_p_two1_collision_collision_4'>
        <pose>0.11194999999999999 0 -0.045249999999999999 0 0 0</pose>
        <geometry>
          <box>
            <size>0.053900000000000003 0.0402 0.0015</size>
          </box>
        </geometry>
      </collision>
      <visual name='right_leg_pitch_visual_visual'>
        <pose>0 0 0 -1.5707963270000003 0 0</pose>
        <geometry>
          <mesh>
            <scale>1 1 1</scale>
            <uri>meshes/right_leg_pitch.STL</uri>
          </mesh>
        </geometry>
        <material>
          <diffuse>0 0 0 1</diffuse>
          <ambient>0 0 0 1</ambient>
        </material>
      </visual>
    </link>
    <joint name='right_knee' type='revolute'>
      <pose relative_to='right_leg_pitch'>0.130031979223655 0.00048990148211499999 -0.0046577221596699999 0 0 0</pose>
      <parent>right_leg_pitch</parent>
      <child>right_leg_knee</child>
      <axis>
        <xyz>-1.8970996919654559e-17 0 -1</xyz>
        <limit>
          <lower>-3.1415926540000001</lower>
          <upper>3.1415926540000001</upper>
          <effort>10</effort>
          <velocity>20</velocity>
        </limit>
        <dynamics>
          <damping>0.036200000000000003</damping>
          <friction>0.0077999999999999996</friction>
          <spring_reference>0</spring_reference>
          <spring_stiffness>0</spring_stiffness>
        </dynamics>
      </axis>
    </joint>
    <link name='right_leg_knee'>
      <pose relative_to='right_knee'>0 0 0 0 0 0</pose>
      <inertial>
        <pose>0.084360000000000004 0 -0.022872 0 0 0</pose>
        <mass>0.0328192125267944</mass>
        <inertia>
          <ixx>1.9489049933254499e-06</ixx>
          <ixy>-1.4998438866811501e-20</ixy>
          <ixz>4.7964550293966002e-12</ixz>
          <iyy>4.3073341622455502e-05</iyy>
          <iyz>4.6518569698450903e-22</iyz>
          <izz>4.4968042537653101e-05</izz>
        </inertia>
      </inertial>
      <collision name='right_leg_knee_collision0_collision'>
        <pose>0 0 -0.049750000000000003 0 0 0</pose>
        <geometry>
          <cylinder>
            <length>0.0054999999999999997</length>
            <radius>0.014</radius>
          </cylinder>
        </geometry>
      </collision>
      <collision name='right_leg_knee_collision1_collision_1'>
        <pose>0 0 0.0030000000000000001 0 0 0</pose>
        <geometry>
          <cylinder>
            <length>0.0054999999999999997</length>
            <radius>0.014</radius>
          </cylinder>
        </geometry>
      </collision>
      <collision name='right_leg_knee_collision2_collision_2'>
        <pose>0.13036 0 -0.049750000000000003 0 0 0</pose>
        <geometry>
          <cylinder>
            <length>0.0054999999999999997</length>
            <radius>0.014</radius>
          </cylinder>
        </geometry>
      </collision>
      <collision name='right_leg_knee_collision3_collision_3'>
        <pose>0.13036 0 0.0030000000000000001 0 0 0</pose>
        <geometry>
          <cylinder>
            <length>0.0054999999999999997</length>
            <radius>0.014</radius>
          </cylinder>
        </geometry>
      </collision>
      <visual name='right_leg_knee_visual_visual'>
        <pose>0 0 0 -1.5707963270000003 0 0</pose>
        <geometry>
          <mesh>
            <scale>1 1 1</scale>
            <uri>meshes/right_leg_knee.STL</uri>
          </mesh>
        </geometry>
        <material>
          <diffuse>0 0 0 1</diffuse>
          <ambient>0 0 0 1</ambient>
        </material>
      </visual>
    </link>
    <joint name='right_ankle_pitch' type='revolute'>
      <pose relative_to='right_leg_knee'>0.12997626654429101 0.00048990148211499999 0.0039420973789790004 1.5671599999998351 -1.568380000000182 -1.5709099999998204</pose>
      <parent>right_leg_knee</parent>
      <child>right_leg_ankle</child>
      <axis>
        <xyz>1 0 0</xyz>
        <limit>
          <lower>-3.1415926540000001</lower>
          <upper>3.1415926540000001</upper>
          <effort>10</effort>
          <velocity>20</velocity>
        </limit>
        <dynamics>
          <damping>0.036200000000000003</damping>
          <friction>0.0077999999999999996</friction>
          <spring_reference>0</spring_reference>
          <spring_stiffness>0</spring_stiffness>
        </dynamics>
      </axis>
    </joint>
    <link name='right_leg_ankle'>
      <pose relative_to='right_ankle_pitch'>0 0 0 0 0 0</pose>
      <inertial>
        <pose>-0.026509000000000001 -0.016018000000000001 0.014279999999999999 0 0 0</pose>
        <mass>0.17394820501059499</mass>
        <inertia>
          <ixx>6.1525563468979203e-05</ixx>
          <ixy>-4.3542375080641399e-11</ixy>
          <ixz>1.0731643525882001e-07</ixz>
          <iyy>6.5767469449289794e-05</iyy>
          <iyz>-1.90056299790816e-07</iyz>
          <izz>3.8828439931667398e-05</izz>
        </inertia>
      </inertial>
      <collision name='right_leg_ankle_small_collision_collision'>
        <pose>-0.026608 -0.043499999999999997 0.014751999999999999 0 0 0</pose>
        <geometry>
          <box>
            <size>0.028984800000000002 0.041000000000000002 0.055496200000000002</size>
          </box>
        </geometry>
      </collision>
      <collision name='right_leg_ankle_small11_collision_collision_1'>
        <pose>-0.026599999999999999 -0.058250000000000003 0.01755 0 0 0</pose>
        <geometry>
          <box>
            <size>0.029000000000000001 0.0044999999999999997 0.061100000000000002</size>
          </box>
        </geometry>
      </collision>
      <collision name='right_leg_ankle_small12_collision_collision_2'>
        <pose>-0.026599999999999999 -0.058250000000000003 0.01755 0 0 0</pose>
        <geometry>
          <box>
            <size>0.0402 0.0044999999999999997 0.0499</size>
          </box>
        </geometry>
      </collision>
      <collision name='right_leg_ankle_small21_collision_collision_3'>
        <pose>-0.026599999999999999 -0.028739000000000001 0.01755 0 0 0</pose>
        <geometry>
          <box>
            <size>0.029000000000000001 0.0044999999999999997 0.061100000000000002</size>
          </box>
        </geometry>
      </collision>
      <collision name='right_leg_ankle_small22_collision_collision_4'>
        <pose>-0.026599999999999999 -0.028739000000000001 0.01755 0 0 0</pose>
        <geometry>
          <box>
            <size>0.0402 0.0044999999999999997 0.0499</size>
          </box>
        </geometry>
      </collision>
      <collision name='right_leg_ankle_big_collision_collision_5'>
        <pose>-0.026599999999999999 0 0.01525 0 0 0</pose>
        <geometry>
          <box>
            <size>0.045999999999999999 0.029000000000000001 0.059499999999999997</size>
          </box>
        </geometry>
      </collision>
      <collision name='right_leg_ankle_big11_collision_collision_6'>
        <pose>-0.041849999999999998 0 0.01805 0 0 0</pose>
        <geometry>
          <box>
            <size>0.0035000000000000001 0.029000000000000001 0.065100000000000005</size>
          </box>
        </geometry>
      </collision>
      <collision name='right_leg_ankle_big12_collision_collision_7'>
        <pose>-0.041849999999999998 0 0.01805 0 0 0</pose>
        <geometry>
          <box>
            <size>0.0035000000000000001 0.0402 0.053900000000000003</size>
          </box>
        </geometry>
      </collision>
      <collision name='right_leg_ankle_big21_collision_collision_8'>
        <pose>-0.0111 0 0.01805 0 0 0</pose>
        <geometry>
          <box>
            <size>0.0030000000000000001 0.029000000000000001 0.065100000000000005</size>
          </box>
        </geometry>
      </collision>
      <collision name='right_leg_ankle_big22_collision_collision_9'>
        <pose>-0.0111 0 0.01805 0 0 0</pose>
        <geometry>
          <box>
            <size>0.0035000000000000001 0.0402 0.053900000000000003</size>
          </box>
        </geometry>
      </collision>
      <collision name='right_leg_ankle_upper_collision_collision_10'>
        <pose>-0.026599999999999999 0.02785 0.0070000000000000001 0 0 0</pose>
        <geometry>
          <box>
            <size>0.039 0.0027000000000000001 0.029999999999999999</size>
          </box>
        </geometry>
      </collision>
      <visual name='right_leg_ankle_visual_visual'>
        <pose>0 0 0 -1.5707963270000003 0 0</pose>
        <geometry>
          <mesh>
            <scale>1 1 1</scale>
            <uri>meshes/right_leg_ankle.STL</uri>
          </mesh>
        </geometry>
        <material>
          <diffuse>0 0 0 1</diffuse>
          <ambient>0 0 0 1</ambient>
        </material>
      </visual>
    </link>
    <joint name='right_ankle_roll' type='revolute'>
      <pose relative_to='right_leg_ankle'>-0.026765899999999999 -0.069436100000000001 -0.000164943 -0.002392653589793028 0.0064826535897931767 -1.2653589793421364e-05</pose>
      <parent>right_leg_ankle</parent>
      <child>right_foot</child>
      <axis>
        <xyz>0 -1 0</xyz>
        <limit>
          <lower>-3.1415926540000001</lower>
          <upper>3.1415926540000001</upper>
          <effort>7</effort>
          <velocity>20</velocity>
        </limit>
        <dynamics>
          <damping>0.036200000000000003</damping>
          <friction>0.0077999999999999996</friction>
          <spring_reference>0</spring_reference>
          <spring_stiffness>0</spring_stiffness>
        </dynamics>
      </axis>
    </joint>
    <link name='right_foot'>
      <pose relative_to='right_ankle_roll'>0 0 0 0 0 0</pose>
      <inertial>
        <pose>0.012889344838027599 0.068349573591404394 -0.036000558661549199 0 0 0</pose>
        <mass>0.14342863960313501</mass>
        <inertia>
          <ixx>0.00014133738462663599</ixx>
          <ixy>3.7013888509899199e-12</ixy>
          <ixz>-2.0333584432894299e-12</ixz>
          <iyy>5.0459643793834899e-05</iyy>
          <iyz>-3.2037887084776298e-07</iyz>
          <izz>0.000183618491010819</izz>
        </inertia>
      </inertial>
      <collision name='right_foot_box1_collision_collision'>
        <pose>-0.016188000000000001 0.066000000000000003 -0.040925999999999997 0 0 0</pose>
        <geometry>
          <box>
            <size>0.089999999999999997 0.126 0.016</size>
          </box>
        </geometry>
      </collision>
      <collision name='right_foot_box2_collision_collision_1'>
        <pose>-0.016211 0.066022999999999998 -0.040925999999999997 0 0 0</pose>
        <geometry>
          <box>
            <size>0.065954399999999996 0.149954 0.012</size>
          </box>
        </geometry>
      </collision>
      <collision name='right_foot_box3_collision_collision_2'>
        <pose>-0.016188000000000001 0.066000000000000003 -0.040925999999999997 0 0 0</pose>
        <geometry>
          <box>
            <size>0.086999999999999994 0.14699999999999999 0.0060000000000000001</size>
          </box>
        </geometry>
      </collision>
      <collision name='right_foot_box4_collision_collision_3'>
        <pose>-0.016171999999999999 0.14108599999999999 -0.037588999999999997 0 0 0</pose>
        <geometry>
          <box>
            <size>0.089999999999999997 0.0058276400000000003 0.018674400000000001</size>
          </box>
        </geometry>
      </collision>
      <collision name='right_foot_cylinder11_collision_collision_4'>
        <pose>0.022706 0.13550000000000001 -0.057119000000000003 0 0 0</pose>
        <geometry>
          <cylinder>
            <length>0.014</length>
            <radius>0.0030000000000000001</radius>
          </cylinder>
        </geometry>
      </collision>
      <collision name='right_foot_cylinder12_collision_collision_5'>
        <pose>0.022706 0.13550000000000001 -0.047119000000000001 0 0 0</pose>
        <geometry>
          <cylinder>
            <length>0.0060000000000000001</length>
            <radius>0.0054999999999999997</radius>
          </cylinder>
        </geometry>
      </collision>
      <collision name='right_foot_cylinder21_collision_collision_6'>
        <pose>-0.055293000000000002 0.13550000000000001 -0.057119000000000003 0 0 0</pose>
        <geometry>
          <cylinder>
            <length>0.014</length>
            <radius>0.0030000000000000001</radius>
          </cylinder>
        </geometry>
      </collision>
      <collision name='right_foot_cylinder22_collision_collision_7'>
        <pose>-0.055293000000000002 0.13550000000000001 -0.047119000000000001 0 0 0</pose>
        <geometry>
          <cylinder>
            <length>0.0060000000000000001</length>
            <radius>0.0054999999999999997</radius>
          </cylinder>
        </geometry>
      </collision>
      <collision name='right_foot_cylinder31_collision_collision_8'>
        <pose>0.022706 -0.0035000000000000001 -0.057119000000000003 0 0 0</pose>
        <geometry>
          <cylinder>
            <length>0.014</length>
            <radius>0.0030000000000000001</radius>
          </cylinder>
        </geometry>
      </collision>
      <collision name='right_foot_cylinder32_collision_collision_9'>
        <pose>0.022706 -0.0035000000000000001 -0.047119000000000001 0 0 0</pose>
        <geometry>
          <cylinder>
            <length>0.0060000000000000001</length>
            <radius>0.0054999999999999997</radius>
          </cylinder>
        </geometry>
      </collision>
      <collision name='right_foot_cylinder41_collision_collision_10'>
        <pose>-0.055293000000000002 -0.0035000000000000001 -0.057119000000000003 0 0 0</pose>
        <geometry>
          <cylinder>
            <length>0.014</length>
            <radius>0.0030000000000000001</radius>
          </cylinder>
        </geometry>
      </collision>
      <collision name='right_foot_cylinder42_collision_collision_11'>
        <pose>-0.055293000000000002 -0.0035000000000000001 -0.047119000000000001 0 0 0</pose>
        <geometry>
          <cylinder>
            <length>0.0060000000000000001</length>
            <radius>0.0054999999999999997</radius>
          </cylinder>
        </geometry>
      </collision>
      <visual name='right_foot_visual_visual'>
        <pose>0 0 0 -1.5707963270000003 0 0</pose>
        <geometry>
          <mesh>
            <scale>1 1 1</scale>
            <uri>meshes/right_foot.STL</uri>
          </mesh>
        </geometry>
        <material>
          <diffuse>0 0 0 1</diffuse>
          <ambient>0 0 0 1</ambient>
        </material>
      </visual>
    </link>
    <frame name='head_pitch' attached_to='neck'>
      <pose>-0.018749999999999999 0 0.043799999999999999 1.5707959999999983 -1.4912129999999999 -1.5707959999999981</pose>
    </frame>
    <frame name='head' attached_to='head_pitch'>
      <pose>0 0 0 0 0 0</pose>
    </frame>
    <frame name='head_yaw' attached_to='chest'>
      <pose>0 0.0134 0.02075000000000005 0 0 0</pose>
    </frame>
    <frame name='neck' attached_to='head_yaw'>
      <pose>0 0 0 0 0 0</pose>
    </frame>
  </model>
</sdf>
